## promise面试题？

https://interview.poetries.top/qa/3-Promise%E9%9D%A2%E8%AF%95%E9%A2%98.html

##  43 道 JavaScript 面试题？
https://juejin.cn/post/6844903869378461710

## [] == ![]结果是什么？为什么？

**结果为 true**

**比较运算符，如果某一方是引用类型，则会转为原始值后比较。**

**如果都是引用类型，比较引用地址即可。。**

1. 左侧空数组`[]`，`[].valueOf().toString()` 是 `''` 空字符串
2. 右侧`![] `逻辑非优先级 大于 比较运算符，所以首先是转换为布尔值，由于`[]`作为一个引用类型转换为布尔值为 `true`, 因此`![]`为 `false`
3. 最后 `'' == false` 在进行一次隐式转换，所以为 `true`

## [] == 0 ?

**结果为 true**

1. `[].valueOf ().toString ()  == ''`
2. `'' == 0`

## ![] == 0 ?

**结果为 true**

1. 一元运算符优先级高于二元运算符, `![] = false`
2. `false == 0`

## {} == 0 ?

**结果为 false**

1. `{}.valueOf ().toString ()  == '[object Object]'`
2. `[object Object]' == 0`

## !{} == 0 ?

**结果为 true**

1. 一元运算符优先级高于二元运算符, `!{} = false`
2. `false == 0`

## 0 == null ?
**结果为 false**

具体结果步骤 参考：https://es6.ruanyifeng.com/#docs/spec#%E7%9B%B8%E7%AD%89%E8%BF%90%E7%AE%97%E7%AC%A6

总结：
- 同类型比较时，执行严格相等运算 x === y
- undefined 与 null 比较时返回 true
- string 与 number 进行比较时，先将 string 做 ToNumber 处理，再进行比较
- boolean 与其它类型进行比较时，先将 boolean 做 ToNumber 处理，再进行比较
- 引用类型 与 基本类型 进行比较时，将 引用类型 做 ToPrimitive 处理，再进行比较
- undefined null 与其它类型的比较时都返回 false


## 一个中文占多少字节？

一个中文字符占用多少字节跟编码密切相关，不能直接说一个中文占 2 个或者 3 个字节，比如 `UTF-8` 编码下一个中文字符通常占用 3 个字节。

## 一个汉子的'中'.length 长度是多少，一个表情 "😊".length 的长度是多少，为什么？

```js
"中".length; // 1
"😊".length; // 2
```

在 JavaScript 中，通常使用 `UTF-16 `编码。而我们的网页通常是 `UTF-8` 编码，所以使用 javascript 内部的字符串方法时，实际上内部会做一个转换, 是以 utf-16 为准。

通常一个汉字的 `length` 属性是 1，因为在 `unicode` 字符集中的数字大小，只需要 `utf-16` 用两个字节保存即可。

有些数字较大，超过了两个字节表示的范围，就需要 4 个字节表示。

## 什么是补码，补码有什么作用？（难）

**补码：** 使用补码表示法，可以将减法转化为加法，这样加法和减法都可以在加法器上进行运算，简化了计算机的设计和实现。
`例如 2 - 4 可以换算为 2 + (-4)。`

在补码表示法中，正数的补码与其二进制表示形式相同。负数的补码由对应正数的补码按位取反（即 0 变为 1，1 变为 0），然后再加 1 得到。

基本原理，我们拿时钟举例：
在时钟上，时针加上（正拨）12 的整数位或减去（反拨）12 的整数位，时针的位置不变。14 点钟在舍去模 12 后，成为（下午）2 点钟（14=14-12=2）。从 0 点出发逆时针拨 10 格即减去 10 小时，也可看成从 0 点出发顺时针拨 2 格（加上 2 小时），即 2 点（0-10=-10=-10+12=2）。因此，在模 12 的前提下，-10 可映射为+2。

举例：
在 JavaScript 中，可以使用按位非(~)运算符来实现取反操作，使用按位与(&)运算符来实现加 1 操作。以下是一个实现减法运算的例子：

```js
function subtract(a, b) {
  b = ~b + 1;
  return a + b;
}
subtract(10, 8); // 2
```

## 0.1+0.2 为什么不等于 0.3？如何让其相等？ 0.1+0.1 为什么等于 0.2？

> 在 IEEE 754 标准中，浮点数的表示是有限的，0.1 和 0.2 在转换成二进制后会无限循环，因为在 IEEE 754 标准中的 64 位浮点数的小数部分，最多有 53 位, 2 的 53 次方就是 16 位数字，所以小数部分最多展示 16 位，由于标准位数的限制后面多余的位数会被截掉，此时就已经出现了精度的损失，相加后因浮点数小数位的限制而截断的二进制数字在转换为十进制就会变成 0.30000000000000004

**<font color="red">所以 0.1+0.2 不等于 0.3</font>**

```js
(0.1).toPrecision(16); // "0.1000000000000000"
(0.1).toPrecision(17); // "0.10000000000000001";
```

**<font color="red">所以 0.1 + 0.1 正好 16 位（四舍五入）截断，等于 0.2。</font>**

**解决办法：**

**ES6 提供的 Number.EPSILON 常量**

Number.EPSILON 的实质是一个可以接受的最小误差范围，一般来说为 `Math.pow(2, -52)`

```js
function isEqual(a, b) {
  return Math.abs(a - b) < Number.EPSILON;
}

console.log(isEqual(0.1 + 0.2, 0.3)); // true
```

**乘以一个 10 的幂次方**

把需要计算的数字乘以 10 的 n 次方，让数值都变为整数，计算完后再除以 10 的 n 次方，这样就不会出现浮点数精度丢失问题

```js
(0.1 * 10 + 0.2 * 10) / 10 == 0.3; //true
```

## 如何让 if(a == 1 && a == 2)条件成立？

涉及到隐式类型转换，对象转换成基本数据类型会调用内置的`[ToPrimitive]`函数，对于该函数而言，其逻辑如下：

- 如果有 `Symbol.toPrimitive()`方法，优先调用再返回
- 调用 `valueOf()`，如果转换为原始类型，则返回
- 调用 `toString()`，如果转换为原始类型，则返回
- 如果都没有返回原始类型，会报错

```js
let obj = {
  value: 3,
  valueOf() {
    return 4;
  },
  toString() {
    return "5";
  },
  [Symbol.toPrimitive]() {
    return 6;
  },
};
console.log(obj + 1); // 输出7
```

所以可以使用 **重写/覆盖** 以上任何一个 方法即可

```js
let a = {
  value: 0,
  valueOf: function () {
    this.value++;
    return this.value;
  },
};
console.log(a == 1 && a == 2); // true
```

## 以下代码的 console.log(2); 会执行吗，什么时候执行？

```js
new Promise((resolve, reject) => {
  resolve(1);
  console.log(2);
}).then((res) => {
  console.log(res);
});
```

::: details
会执行，执行顺序是：2、1

这是因为立即 `resolved` 的 `Promise` 是在本轮事件循环的末尾执行，总是晚于本轮循环的同步任务。
:::

## 以下代码的 console.log(2); 会执行吗，什么时候执行？

```js
new Promise((resolve, reject) => {
  return resolve(1);
  console.log(2);
}).then((res) => {
  console.log(res);
});
```

::: details
不会执行，因为有 return
:::

## 以下代码的执行顺序，为什么？

```js
let promise = new Promise(function (resolve, reject) {
  console.log("Promise");
  resolve();
});

promise.then(function () {
  console.log("resolved.");
});

setTimeout(function () {
  console.log("setTimeout");
});

console.log("Hi!");
```

::: details

1. 创建 promise 实例，是一个同步操作，会立即执行，打印：`Promise`
2. 遇到 promise 结果是一个微任务，放到当前的微任务队列，下边遇到 setTimeout 是一个宏任务，放到宏任务队列，然后执行同步代码 console.log('Hi!')，打印：`Hi!`
3. 同步代码执行完毕后，执行微任务队列，打印：`resolved.`
4. 微任务执行完，执行宏任务队列，打印：`setTimeout`

```js
// 打印：
// Promise
// Hi!
// resolved.
// setTimeout
```

:::

## 以下代码 打印什么？

```js
const p1 = new Promise(function (resolve, reject) {
  setTimeout(() => reject(new Error("fail")), 3000);
});

const p2 = new Promise(function (resolve, reject) {
  setTimeout(() => resolve(p1), 1000);
});

p2.then((result) => console.log(result)).catch((error) => console.log(error));
```

::: details
**打印 `Error: fail`**

`p1` 是一个 Promise，3 秒之后变为`rejected`。`p2`的状态在 1 秒之后改变，`resolve`方法返回的是`p1`。由于`p2`返回的是另一个 Promise，导致`p2`自己的状态无效了，由`p1`的状态决定`p2`的状态。所以，后面的`then`语句都变成针对后者（`p1`）。又过了 2 秒，`p1`变为`rejected`，导致触发`catch`方法指定的回调函数。
:::

## 可以捕获到这个错误吗(如何捕获 promise 内部的错误)？

```js
try {
  const promise = new Promise(function (resolve, reject) {
    throw new Error("test");
  });
} catch (e) {
  console.log(e, "catch");
}
```

::: details
不可以，外部无法捕获到 promise 内部的错误。

可以以下方式解决：

```js
// 写法一
const promise = new Promise(function (resolve, reject) {
  try {
    throw new Error("test");
  } catch (e) {
    reject(e);
  }
});
promise.catch(function (error) {
  console.log(error);
});

// 写法二
const promise = new Promise(function (resolve, reject) {
  reject(new Error("test"));
});
promise.catch(function (error) {
  console.log(error);
});
```

:::

## 打印什么？

```js
const promise = new Promise(function (resolve, reject) {
  resolve("ok");
  throw new Error("test");
});
promise
  .then(function (value) {
    console.log(value);
  })
  .catch(function (error) {
    console.log(error);
  });
```

::: details
**<font color="red">打印 ok</font>**

`Promise` 在 `resolve` 语句后面，再抛出错误，不会被捕获，等于没有抛出。因为 `Promise` 的状态一旦改变，就永久保持该状态，不会再变了。

:::

## 以下代码可以捕获前面 promise 的错误么？

```js
getJSON("/post/1.json")
  .then(function (post) {
    return getJSON(post.commentURL);
  })
  .then(function (comments) {
    // some code
  })
  .catch(function (error) {
    // 可以 捕获到 前面三个Promise产生的错误吗？
  });
```

::: details
**<font color="red">可以</font>**

`Promise` 对象的错误具有<font color="red">“冒泡”</font>性质，会一直向后传递，直到被捕获为止。也就是说，错误总是会被下一个`catch`语句捕获。

上面代码中，一共有三个 `Promise` 对象：一个由`getJSON()`产生，两个由`then()`产生。它们之中任何一个抛出的错误，都会被最后一个`catch()`捕获。

> 不要在 then()方法里面定义 Reject 状态的回调函数（即 then 的第二个参数），总是使用 catch 方法。这样就可以捕获到前面所有的 promise 错误。

:::

## 以下 Promise.all 的 catch 方法能捕获到 p2 的错误吗？

```js
const p1 = new Promise((resolve, reject) => {
  resolve("hello");
})
  .then((result) => result)
  .catch((e) => e);

const p2 = new Promise((resolve, reject) => {
  throw new Error("报错了");
})
  .then((result) => result)
  .catch((e) => e);

Promise.all([p1, p2])
  .then((result) => console.log(result))
  .catch((e) => console.log(e)); // 这里可以捕获到 p2的错误吗？
```

::: details
**<font color="red">不可以</font>**

上面代码中，`p1`会`resolved`，`p2`首先会`rejected`，但是`p2`有自己的`catch`方法，该方法返回的是一个新的 `Promise` 实例，`p2`指向的实际上是这个实例。该实例执行完`catch`方法后，也会变成`resolved`，导致`Promise.all()`方法参数里面的两个实例都会`resolved`，因此会调用`then`方法指定的回调函数，而不会调用`catch`方法指定的回调函数。

最后打印：`["hello", Error: 报错了]`

:::

## 以下 Promise.all 的 catch 方法能捕获到 p2 的错误吗？

```js
const p1 = new Promise((resolve, reject) => {
  resolve("hello");
}).then((result) => result);

const p2 = new Promise((resolve, reject) => {
  throw new Error("报错了");
}).then((result) => result);

Promise.all([p1, p2])
  .then((result) => console.log(result))
  .catch((e) => console.log(e)); // 这里可以捕获到 p2的错误吗？
```

::: details
**<font color="red">可以</font>**

和上边的题一样，只不过`p2`没有自己的`catch`方法，就会调用`Promise.all()`的`catch`方法。

:::

## 以下代码有什么区别？

```js
// 代码一
let foo = await getFoo();
let bar = await getBar();

// 代码二
let [foo, bar] = await Promise.all([getFoo(), getBar()]);

// 代码三
let fooPromise = getFoo();
let barPromise = getBar();
let foo = await fooPromise;
let bar = await barPromise;
```

::: details

**代码一**

`getFoo`和`getBar`是两个独立的异步操作（即互不依赖），被写成继发关系。这样比较耗时，因为只有`getFoo`完成以后，才会执行`getBar`，完全可以让它们同时触发。

**代码二 和 代码三**

`getFoo`和`getBar` 并发触发，这样就会缩短程序的执行时间

:::

## 下边代码依次打印什么，为什么？

```html
<script type="text/javascript">
  console.log("第一个脚本 begin。。。");

  Promise.resolve().then((res) => {
    console.log("第一个脚本 promise");
  });

  console.log("第一个脚本 end。。。");
</script>

<script type="text/javascript">
  console.log("第二个脚本 begin。。。");

  Promise.resolve().then((res) => {
    console.log("第二个脚本 promise");
  });
  console.log("第二个脚本 end。。。");
</script>
```

::: details
依次打印：

- 第一个脚本 begin。。。
- 第一个脚本 end。。。
- 第一个脚本 promise
- 第二个脚本 begin。。。
- 第二个脚本 end。。。
- 第二个脚本 promise

实际上如果同时存在两个 `script` 代码块，会首先在执行第一个 `script` 代码块中的同步代码，如果这个过程中创建了微任务并进入了微任务队列，第一个 `script` 同步代码执行完之后，会首先去清空微任务队列，再去开启第二个 `script` 代码块的执行。**所以这里应该就可以理解 `script`（整体代码块）为什么会是宏任务。**

:::

## 以下打印顺序？

```js
setTimeout(() => {
    console.log('timeout')
}, 0)                                       

new Promise(resolve => {
    console.log('new Promise')              
    resolve()
}).then(() => {
   console.log('Promise then')             
}).then(() => {
        console.log('Promise then then')   
})

console.log('hi')
```

## 以下打印顺序？

```js
console.log("1", Date.now());

const p = new Promise((resolve, reject) => {
  console.log("2", Date.now());

  setTimeout(() => {
    console.log("3", Date.now());
    resolve("finished");
  }, 500);

  setTimeout(() => {
    console.log("5", Date.now());
    resolve("finished");
  }, 600);
});

p.then(
  (data) => {
    console.log(data);
    console.log("4", Date.now());
  },
  (err) => {
    console.log(err);
    console.log("6", Date.now());
  }
);
```
:::details
注意两个点：

1️⃣ reject是否会执行？（Promise的状态变为fulfilled｜rejected，就无法改变）

2️⃣ .then中的代码一定是Promise的状态已经变为fulfilled｜rejected了才会执行，并且会根据具体状态择一执行

:::